Workbook

Sheet RESUMO
B1: TOTAL DE COMISSÕES ADESÃO 05/26 | E1: #VALUE!
B5: SETOR: COMERCIAL INTERNO
B7: SETOR / SEDE | D7: VALOR TOTAL GERADO | E7: VALOR TOTAL COMISSÃO | F7: VALOR INDIVIDUAL COMISSÃO | G7: COLABORADOR (A)
B9: COMERCIAL | D9: =SUM(COMERCIAL!C65:C66) -> 9462.25 | E9: =D9*20% -> 1892.45 | F9: =COMERCIAL!D65 -> 1247.798 | G9: ÍRIS CAROLINE SANTOS CARVALHO
F10: =COMERCIAL!D66 -> 644.652 | G10: MARIA LUIZA ALMEIDA DE OLIVEIRA
B12: PETROLINA | D12: =PETROLINA!F8 -> 130 | E12: =PETROLINA!D16 -> 26 | F12: =PETROLINA!D16 -> 26 | G12: ARIELLE BORGES DIAS
B14: ITABUNA | D14: =ITABUNA!F8 -> 950 | E14: =D14*20% -> 190 | F14: =ITABUNA!D18 -> 190 | G14: CAMILA DO NASCIMENTO SENA
B16: JUAZEIRO | D16: =JUAZEIRO!F8 -> 3840 | E16: =D16*20% -> 768 | F16: =JUAZEIRO!D19 -> 768 | G16: ANNA ALICE SILVA CARDOSO
B18: JUAZEIRO DO NORTE | D18: ='JUAZEIRO DO NORTE'!F8 -> 0 | E18: =D18*20% -> 0 | F18: ='JUAZEIRO DO NORTE'!D16 -> 0 | G18: YASMIN ALCANTARA ALVES
B20: SENHOR DO BONFIM | D20: ='SENHOR DO BONFIM'!F8 -> 0 | E20: ='SENHOR DO BONFIM'!D16 -> 0 | F20: ='SENHOR DO BONFIM'!D16 -> 0 | G20: MARIA FERNANDA FIGUEIREDO DOS SANTOS
D22: TOTAL VALOR COMISSÃO | F22: =SUM(E9:E16) -> 2876.45
D24: TOTAL VALOR ADESÃO | F24: =SUM(D9:D16) -> 14382.25
D26: TOTAL VALOR LIQUIDO AVP | F26: =F24-F22 -> 11505.8

Sheet COMERCIAL
B1: CONTROLE DE ADESÕES 05/26 | G1: #VALUE!
B5: COLABORADORES RESPONSAVEIS: IRIS CAROLINE E MARIA LUIZA | H5: SETOR: COMERCIAL INTERNO
B7: NÚMERO DE PLACAS: | C7: =COUNTIF(C10:C34, "<>") -> 22 | E7: VALOR TOTAL ADESÕES | F7: =SUM(F10:F34) -> 6238.99 | H7: VALOR TOTAL MENSALIDADES | J7: =SUM(G10:G34) -> 3931.04
B9: Associado | C9: Placa | D9: Data Ativação | E9: Origem do Lead / Vistoria | F9: Adesão | G9: Mensalidade | H9: Colaboradora | I9: Link Comprovantes | J9: CONF. (Financeiro)
B10: HAMANDA AMORIM MACHADO | C10: PDZ9J90 | E10: WhatsApp/Aplicativo | F10: 125 | G10: 52.11 | H10: Iris | I10: HAMANDA AMORIM MACHADO.jpeg | J10: TRUE
B11: TAYNARA VIANA GOMES | C11: PCZ5323 | E11: WhatsApp/Aplicativo | F11: 140 | G11: 85.91 | H11: Iris | I11: TAYNARA VIANA GOMES.pdf | J11: TRUE
B12: LAERCIO FERNANDO DA SILVA SANTOS | C12: KKB3H82 | E12: WhatsApp/Aplicativo | F12: 190 | G12: 119.77 | H12: Iris | I12: LAERCIO FERNANDO DA SILVA SANTOS.pdf | J12: TRUE
B13: RENATO FELIPE DOS SANTOS | C13: PCM5H09 | E13: WhatsApp/Aplicativo | F13: 190 | G13: 136.76 | H13: Iris | I13: RENATO FELIPE DOS SANTOS.pdf | J13: TRUE
B14: PEDRO GUILHERME SERAFIM CARVALHO | C14: LTU8H15 | E14: WhatsApp/Aplicativo | F14: 300 | G14: 145.71 | H14: Iris | I14: PEDRO GUILHERME SERAFIM CARVALHO.jpeg | J14: TRUE
B15: LAURA EMILY ALVES ANDRADE | C15: PCO8E35 | E15: WhatsApp/Aplicativo | F15: 300 | G15: 188.62 | H15: Iris | I15: LAURA EMILY ALVES ANDRADE.jpeg | J15: TRUE
B16: GABRIEL RODRIGUES DE CARVALHO | C16: UHU8I69 | E16: WhatsApp/Aplicativo | F16: 150 | G16: 105.9 | H16: Iris | I16: GABRIEL RODRIGUES DE CARVALHO.pdf | J16: TRUE
B17: MANOEL DA SILVA | C17: SKE7J77 | E17: WhatsApp/Aplicativo | F17: 290 | G17: 154.71 | H17: Iris | I17: MANOEL DA SILVA.jpeg | J17: FALSE
B18: A. M. DISTRIBUIDORA DE BATERIAS LTDA | C18: OHF1G66 | E18: WhatsApp/Aplicativo | G18: 123.17 | H18: Iris | I18: - | J18: TRUE
B19: A. M. DISTRIBUIDORA DE BATERIAS LTDA | C19: OTA4F63 | E19: WhatsApp/Aplicativo | G19: 535.62 | H19: Iris | I19: - | J19: TRUE
B20: A. M. DISTRIBUIDORA DE BATERIAS LTDA | C20: RGU4F63 | E20: WhatsApp/Aplicativo | F20: 1600 | G20: 460 | H20: Iris | I20: A. M. DISTRIBUIDORA DE BATERIAS LTDA.pdf | J20: TRUE
B21: LEILA CARVALHO DE SOUSA | C21: TIC7404 | E21: WhatsApp/Aplicativo | F21: 100 | G21: 100.71 | H21: Iris | I21: LEILA CARVALHO DE SOUSA.jpeg | J21: TRUE
B22: ALLAN TAVARES OLIVEIRA | C22: OTF7H54 | E22: WhatsApp/Aplicativo | F22: 200 | G22: 72.81 | H22: Iris | I22: ALLAN TAVARES OLIVEIRA.jpeg | J22: TRUE
B23: BRUNA LIMA GONÇALVES | C23: OSO9C03 | E23: WhatsApp/Aplicativo | F23: 140 | G23: 63.81 | H23: Iris | I23: BRUNA LIMA GONÇALVES.jpeg | J23: TRUE
B24: EVERTON FELISBERTO SOUZA DA SILVA | C24: PJW0J70 | E24: WhatsApp/Aplicativo | F24: 277.23 | G24: 277.23 | H24: Iris | I24: EVERTON FELISBERTO SOUZA DA SILVA.jpeg | J24: TRUE
B25: LUCAS SILVA RODRIGUES | C25: OYX2061 | E25: WhatsApp/Aplicativo | F25: 136.76 | G25: 136.76 | H25: Iris | I25: LUCAS SILVA RODRIGUES.jpeg | J25: TRUE
B26: CARLA EMILIE CAVALCANTE BRITO | C26: KJS1G21 | E26: WhatsApp/Aplicativo | F26: 150 | G26: 97.67 | H26: Iris | I26: CARLA EMILIE CAVALCANTE BRITO.jpeg | J26: TRUE
B27: MOISES RICARDO DE LIMA SANTOS | E27: WhatsApp/Aplicativo | F27: 140 | G27: 112.41 | H27: Iris | I27: MOISES RICARDO DE LIMA SANTOS .pdf | J27: TRUE
B28: INARA MORGANA DINIZ BEZERRA | C28: OSI6736 | E28: WhatsApp/Aplicativo | F28: 100 | G28: 53.91 | H28: Iris | I28: INARA MORGANA DINIZ BEZERRA.pdf | J28: TRUE
B29: LAZARO GUSTAVO DE LUCCAS | C29: DZH9E25 | E29: WhatsApp/Aplicativo | F29: 300 | G29: 126.06 | H29: Iris | I29: LAZARO GUSTAVO DE LUCCAS.pdf | J29: TRUE
B30: GABRIEL MENEZES COSTA | C30: PDK5786 | E30: WhatsApp/Aplicativo | F30: 450 | G30: 271.06 | H30: Iris | I30: GABRIEL MENEZES COSTA.pdf | J30: TRUE
B31: IAN BRUNO FREIRES DE SÁ | C31: OYX6C74 | E31: WhatsApp/Aplicativo | F31: 180 | G31: 112.41 | H31: Iris | I31: IAN BRUNO FREIRES DE SÁ.pdf | J31: TRUE
B32: JAIRO DIAS RIBEIRO | C32: QLC7G16 | E32: WhatsApp/Aplicativo | F32: 600 | G32: 276.51 | H32: Iris | I32: JAIRO DIAS RIBEIRO.pdf | J32: TRUE
B33: BATISTA PEREIRA DE BARROS | E33: WhatsApp/Aplicativo | F33: 180 | G33: 121.41 | H33: Iris | I33: BATISTA PEREIRA DE BARROS.jpeg | J33: TRUE
B38: TROCA DE TITULARIDADE
B40: Nome do associado | C40: Placa | D40: Data Efetuado | E40: Data pagamento | F40: Situação | G40: VALOR | H40: Atendente
B41: Cristiany De Lima Ramalho | C41: TMR1C69 | D41: 46121 | E41: 46147 | F41: PAGO | G41: 81.83 | H41: LUIZA
B42: Kelly Soares Fonseca | C42: FRP1C97 | D42: 46125 | E42: 46147 | F42: PAGO | G42: 101.32 | H42: LUIZA
B43: Ezequiel Pereira Silva | C43: TGY3C69 | D43: 46128 | E43: 46152 | F43: PAGO | G43: 74.61 | H43: LUIZA
B44: Thaís Santos Da Conceição | C44: RCU0D55 | D44: 46136 | E44: 46152 | F44: PAGO | G44: 59.33 | H44: LUIZA
B45: Anderson Da Silva | C45: PLV0G18 | D45: 46142 | E45: 46152 | F45: PAGO | G45: 82.71 | H45: LUIZA
B46: Raimundo Jose Da Silva Coelho | C46: NPV2G58 | D46: 46146 | E46: 46152 | F46: PAGO | G46: 238.74 | H46: LUIZA
B47: Elder Bernardo De Araujo | C47: ORZ9108 | D47: 46146 | E47: 46162 | F47: PAGO | G47: 71.03 | H47: LUIZA
B48: Andrea Karla Rodrigues Chaves | C48: PLU3B03 | D48: 46146 | E48: 46152 | F48: PAGO | G48: 227.68 | H48: LUIZA
B49: Isaque Costa Gomes Santos | C49: TIJ3B11 | D49: 46147 | E49: 46147 | F49: PAGO | G49: 92.41 | H49: LUIZA
B50: Gustavo Lima Do Nascimento | C50: PLW4I69 | D50: 46149 | E50: 46152 | F50: PAGO | G50: 63.8 | H50: LUIZA
...

Sheet PETROLINA
B1: CONTROLE DE ADESÕES: PETROLINA 05/26 | F1: #VALUE!
B6: COLABORADORAS RESPONSAVEIS: ARIELLE BORGES | F6: SETOR: RECEPÇÃO PETROLINA
B8: NÚMERO DE PLACAS: | C8: =COUNTIF(F11:F12, "<>") -> 1 | E8: VALOR TOTAL ADESÕES | F8: =SUM(F11:F12) -> 130 | H8: VALOR TOTAL MENSALIDADES | J8: =SUM(G11:G12) -> 87.21
B10: Associado | C10: Placa | D10: Data Ativação | E10: Origem Lead | F10: Adesão | G10: Mensalidade | H10: Atendente | I10: Link Comprovante | J10: CONF. (Financeiro)
B11: ARIMAR ADELMAR DA SILVA SA | C11: PDB9D64 | D11: 46146 | E11: PRESECIAL | F11: 130 | G11: 87.21 | H11: Arielle | I11: ARIMAR ADELMAR DA SILVA SA.pdf | J11: 2
B15: COLABORADORA | C15: VALOR TOTAL | D15: COMISSÃO 20%
B16: ARIELLE BORGES | C16: =SUMIF(H11:H12, "ARIELLE", F11:F12) -> 130 | D16: =C16*20% -> 26

Sheet ITABUNA
B1: CONTROLE DE ADESÕES: ITABUNA 05/26 | F1: #VALUE!
B6: COLABORADORA RESPONSAVEL: CAMILA | H6: SETOR: RECEPÇÃO ITABUNA
B8: NÚMERO DE PLACAS | C8: =COUNTA(C11:C14) -> 3 | E8: VALOR TOTAL ADESÕES | F8: =SUM(F11:F14) -> 950 | H8: VALOR TOTAL MENSALIDADES | J8: =SUM(G11:G14) -> 266.13
B10: Associado | C10: Placa | D10: Data Ativação | E10: Origem do Lead / Vistoria | F10: Adesão | G10: Mensalidade | H10: Colaboradora | I10: Link Comprovantes | J10: CONF. (Financeiro)
B11: LUCIMARA SALES SOUSA | C11: TMM8B06 | D11: 46161 | E11: SEDE/ITABUNA | F11: 400 | G11: 74.61 | H11: CAMILA | I11: * | J11: TRUE
B12: EDVALDO ALVES DOS SANTOS JUNIOR | C12: TGU3A99 | D12: 46169 | E12: SEDE/ITABUNA | F12: 350 | G12: 102.51 | H12: CAMILA | I12: * | J12: TRUE
B13: SIDNEI DOS SANTOS PEREIRA | C13: SJS4B77 | D13: 46170 | E13: SEDE/ITABUNA | F13: 200 | G13: 89.01 | H13: CAMILA | I13: * | J13: TRUE
B17: COLABORADOR (A) | C17: VALOR TOTAL | D17: COMISSÃO 20%
B18: CAMILA | C18: =SUMIF(H11:H14, "CAMILA", F11:F14) -> 950 | D18: =C18*20% -> 190

Sheet JUAZEIRO
B1: CONTROLE DE ADESÕES: JUAZEIRO BA 05/26 | F1: #VALUE!
B6: COLABORADORA RESPONSAVEL: ANNA ALICE | H6: SETOR: RECEPÇÃO JUAZEIRO - BA
B8: NÚMERO DE PLACAS | C8: =COUNTA(C11:C15) -> 4 | E8: VALOR TOTAL ADESÕES | F8: =SUM(F11:F15) -> 3840 | H8: VALOR TOTAL MENSALIDADES | J8: =SUM(G11:G15) -> 1790.59
B10: Associado | C10: Placa | D10: Data Ativação | E10: Origem Lead | F10: Adesão | G10: Mensalidade | H10: Atendente | I10: Link Comprovante | J10: CONF. (Financeiro)
B11: ELIANDO SILVA DE SOUZA | C11: FFD6C98 | D11: 46147 | E11: JUAZEIRO - BAHIA | F11: 480 | G11: 267.9 | H11: ANNA ALICE | I11: https://drive.google.com/file/d/1kxUIlTwk7Fx2_pzl9VQYKeVnRnBWZ6Na/view?usp=drive_link | J11: TRUE
B12: AURICELIA BARROS DA SILVA | C12: TMW4D15 | D12: 46153 | E12: JUAZEIRO - BAHIA | F12: 1100 | G12: 400 | H12: ANNA ALICE | I12: https://drive.google.com/file/d/11qEmbn4JoeGJqmYCxfmHpi3cT31Y_fCX/view?usp=drive_link | J12: TRUE
B13: ROBERTO ALMEIDA DOS SANTOS | C13: RFK0A52 | D13: 46162 | E13: JUAZEIRO - BAHIA | F13: 500 | G13: 310.17 | H13: ANNA ALICE | I13: https://drive.google.com/file/d/1dfcr6R4Oxy7ocNjCOynKfydU-_rRF_Gi/view?usp=drive_link | J13: TRUE
B14: JOSÉ CARLOS BARBOSA DA SILVA | C14: TMY7F17 | D14: 46164 | E14: JUAZEIRO - BAHIA | F14: 1760 | G14: 812.52 | H14: ANNA ALICE | I14: https://drive.google.com/file/d/1QizhJOnI72Eo-_fjwFgOfcPdI7prx5Fz/view?usp=drive_link | J14: TRUE
B18: COLABORADORA | C18: VALOR TOTAL | D18: COMISSÃO 20%
B19: ANNA ALICE | C19: =SUMIF(H11:H15, "ANNA ALICE", F11:F15) -> 3840 | D19: =C19*20% -> 768

Sheet JUAZEIRO DO NORTE
B1: CONTROLE DE ADESÕES: JUAZEIRO CE 05/26 | F1: #VALUE!
B6: COLABORADORA RESPONSAVEL: YASMIN ALCANTARA | H6: SETOR: RECEPÇÃO JUAZEIRO - BA
B8: NÚMERO DE PLACAS | C8: =COUNTA(C11:C12) -> 0 | E8: VALOR TOTAL ADESÕES | F8: =SUM(F11:F12) -> 0 | H8: VALOR TOTAL MENSALIDADES | J8: =SUM(G11:G12) -> 0
B10: Associado | C10: Placa | D10: Data Ativação | E10: Origem Lead | F10: Adesão | G10: Mensalidade | H10: Atendente | I10: Link Comprovante | J10: CONF. (Financeiro)
J11: FALSE
B15: COLABORADORA | C15: VALOR TOTAL | D15: COMISSÃO 20%
B16: ANNA ALICE | C16: =SUMIF(H11:H12, "YASMIN", F11:F12) -> 0 | D16: =C16*20% -> 0

Sheet SENHOR DO BONFIM
B1: CONTROLE DE ADESÕES: SR DO BONFIM 05/26 | F1: #VALUE!
B6: COLABORADORA RESPONSAVEL: FERNANDA FIGUEIREDO | H6: SETOR: RECEPÇÃO ITABUNA
B8: NÚMERO DE PLACAS | C8: =COUNTA(C11:C12) -> 0 | E8: VALOR TOTAL ADESÕES | F8: =SUM(F11:F12) -> 0 | H8: VALOR TOTAL MENSALIDADES | J8: =SUM(G11:G12) -> 0
B10: Associado | C10: Placa | D10: Data Ativação | E10: Origem do Lead / Vistoria | F10: Adesão | G10: Mensalidade | H10: Colaboradora | I10: Link Comprovantes | J10: CONF. (Financeiro)
J11: FALSE
B15: COLABORADOR (A) | C15: VALOR TOTAL | D15: COMISSÃO 20%
B16: FERNANDA | C16: =SUMIF(H11:H12, "FERNANDA", F11:F12) -> 0 | D16: =C16*20% -> 0

Sheet DEZEMBRO
B1: SETOR COMERCIAL - DEZEMBRO
B3: Associado | C3: Data de cadastro | D3: Placa | E3: Origem do Lead / Vistoria | F3: Adesão | G3: Mensalidade | H3: Forma de pagamento | I3: Link Comprovantes
B4: FABIO NUNES DOS SANTOS | C4: 01/12/23 | D4: DEO2I91 | E4: Whatsapp / Virtual | F4: 90 | G4: 46.46 | H4: Débito | I4: FABIO NUNES DOS SANTOS.jpeg
B5: DANIELA DE MOLGADO SOARES ARAUJO | C5: 04/12/23 | D5: RPQ2E07 | E5: Whatsapp / Sede De Juazeiro | F5: 90 | G5: 56.9 | H5: Pix | I5: DANIELA DE MORGADO SOARES ARAUJO.jpg
B6: DIOGO JOSE SOUZA DE MACEDO | C6: 04/12/23 | D6: OEM7I79 | E6: Whatsapp / Sede De Petrolina | F6: 210 | G6: 189.47 | H6: Débito | I6: DIOGO JOSE SOUZA DE MACEDO.jpg
B7: RUAN PAULINO NUNES DA SILVA | C7: 05/12/23 | D7: OYL0B96 | E7: Sede Petrolina | F7: 84 | G7: 50.07 | H7: Credito | I7: RUAN PAULINO NUNES DA SILVA.jpg
B8: CICERO FERREIRA DE LIMA | C8: 05/12/23 | D8: QYC9281 | E8: Whatsapp / Vistorias externa | F8: 500 | G8: R$ 328,36 | H8: Pix | I8: CICERO FERREIRA DE LIMA.pdf
B9: SAMILLE DA SILVA SOBREIRA | C9: 05/12/23 | D9: SJL3C92 | E9: Whatsapp / Vistorias consultor | F9: 82 | G9: 60.71 | H9: Pix | I9: SAMILLE DA SILVA SOBREIRA.jpg
B10: FRANCICLEIDE COELHO DE SOUZA | C10: 08/12/23 | D10: RDA9A64 | E10: Whatsapp / Sede De Petrolina | F10: 108 | G10: 65.37 | H10: Especie | I10: FRANCICLEIDE COELHO DE SOUZA.jpeg
B11: JOSE DIONISIO AGUIAR | C11: 09/12/23 | D11: PNJ2C32 | E11: Whatsapp / Sede De Petrolina | F11: 300 | G11: 197.91 | H11: Credito | I11: JOSE DIONISIO AGUIAR.jpeg
B12: ANA CLARA GUIMARAES CARVALHO | C12: 09/12/23 | D12: NZU8D93 | E12: Whatsapp / Virtual | F12: 210 | G12: 125.01 | H12: Pix | I12: ANA CLARA GUIMARAES CARVALHO.pdf
B13: GUSTAVO BATISTA DOS SANTOS NETO | C13: 12/12/23 | D13: SJL4B15 | E13: Whatsapp / Virtual | F13: 200 | G13: 80.9 | H13: Pix | I13: Gustavo Batista Dos Santos Neto.pdf
B14: RUAN PAULINO NUNES DA SILVA | C14: 12/12/23 | D14: RCQ9D56 | E14: Sede Petrolina | F14: 98 | G14: 62.01 | H14: Credito | I14: RUAN PAULINO NUNES DA SILVA.jpeg
B15: RUAN PAULINO NUNES DA SILVA | C15: 14/12/23 | D15: OYS6F98 | E15: Sede Petrolina | F15: 98 | G15: 62.01 | H15: Credito | I15: RUAN PAULINO NUNES DA SILVA2.jpeg
B16: FRANCISCO MARCELO MARTINS DE SA | C16: 15/12/23 | D16: PKG5B78 | E16: Sede Petrolina | F16: 210 | G16: 149.52 | H16: Pix | I16: FRANCISCO MARCELO MARTINS DE SA.jpg
B17: CASSIANO JURACY PEREIRA DA SILVA | C17: 15/12/23 | D17: OYX5344 | E17: Whatsapp / Sede De Juazeiro | F17: 280 | G17: 121.41 | H17: Credito | I17: CASSIANO JURACY PEREIRA DA SILVA.jpegk
B18: CASSIANO JURACY PEREIRA DA SILVA | C18: 15/12/23 | D18: PCE4F78 | E18: Whatsapp / Virtual | F18: 147 | G18: 67.41 | H18: Credito
B19: LUARA ALENCAR DA SILVA | C19: 15/12/23 | D19: SNT3B21 | E19: Whatsapp / Virtual | F19: 180 | G19: 56.56 | H19: Pix | I19: LUARA ALENCAR DA SILVA.pdf
B20: KAMYLLA SUELLY DE ALMEIDA PIRES | C20: 15/12/23 | D20: PGN5378 | E20: Whatsapp / Sede De Petrolina | F20: 240 | G20: 164.61 | H20: Pix | I20: KAMYLLA SUELLY DE ALMEIDA PIRES.jpeg
B21: CINDY RAYANE SENA MONTEIRO | C21: 15/12/23 | D21: SNK4E83 | E21: Whatsapp / Sede De Juazeiro | F21: 200 | G21: 57.51 | H21: Pix | I21: CINDY RAYANE SENA MONTEIRO.jpeg
B22: JACKSON SAULO DE MELO LOPES | C22: 16/12/23 | D22: PEB2F99 | E22: Whatsapp / Sede De Petrolina | F22: 182.9 | G22: 182.9 | H22: Débito | I22: JACKSON SAULO DE MELO LOPES.jpeg
B23: PAULA DAIANE COSTA DOS ANJOS | C23: 16/12/23 | D23: SJP2E47 | E23: Whatsapp / Virtual | F23: 200 | G23: 94.9 | H23: Pix | I23: PAULA DAIANE COSTA DOS ANJOS.jpegk
B24: SOUZA SEGURANCA ELETRONICA | C24: 16/12/23 | D24: QYP6J47 | E24: Sede Petrolina | F24: 190.56 | G24: 190.56 | H24: Débito | I24: SOUZA SEGURANCA ELETRONICA.jpeg
B25: RUAN PAULINO NUNES DA SILVA | C25: 18/12/23 | D25: OYZ8D57 | E25: Sede Petrolina | F25: 98 | G25: 62.01 | H25: Credito | I25: RUAN PAULINO NUNES DA SILVA.jpg
B26: ITALO RODRIGO SILVA BONFIM | C26: 18/12/23 | D26: GHQ4G79 | E26: Whatsapp / Virtual | F26: 400 | G26: 158.8 | H26: Credito | I26: ITALO RODRIGO SILVA BONFIM.jpeg
B27: JOSE NILTON CONCEICAO DE OLIVEIRA | C27: 19/12/23 | D27: RDN9G61 | E27: Whatsapp / Sede De Juazeiro | F27: 480 | G27: 305.92 | H27: Pix | I27: JOSE NILTON CONCEICAO DE OLIVEIRA.jpeg
B28: RUAN PAULINO NUNES DA SILVA | C28: 19/12/23 | D28: OYW0F99 | E28: Whatsapp / Sede De Petrolina | F28: 73.5 | G28: 51.21 | H28: Credito | I28: RUAN PAULINO NUNES DA SILVA3.jpeg
B29: RAFAEL NEVES ALMEIDA ARAUJO FILHO | C29: 22/12/23 | D29: PEI9H66 | E29: Whatsapp / Sede De Juazeiro | F29: 190 | G29: 57.9 | H29: Débito | I29: RAFAEL NEVES ALMEIDA ARAUJO FILHO.jpeg
B30: CAIO MARINO SANTANA BRITO DE BARBOSA | C30: 22/12/23 | D30: NZZ8E44 | E30: Sede Petrolina | F30: 198 | G30: 143.01 | H30: Pix | I30: CAIO MARINO SANTANA BRITO DE BARBOSA.jpg
... B36: JARLENE DE LIMA DA SILVA | C36: 29/12/23 | D36: SNL4I02 | E36: Whatsapp / Sede Petrolina | F36: 144 | G36: 71.01 | H36: Credito | I36: JARLENE DE LIMA DA SILVA.jpg
D38: TOTAL ADESÃO | F38: =SUM(F4:F37) -> 7033.96
D39: TOTAL MENSALIDADE | F39: =SUM(G4:G37) -> 3788.95
D40: NUMERO DE PLACAS | F40: =COUNTIF(B4:B1007,"<>") -> 33

Sheet OUTUBRO
B1: SETOR COMERCIAL - OUTUBRO
B3: Associado | C3: Data de cadastro | D3: Placa | E3: Origem do Lead / Vistoria | F3: Adesão | G3: Mensalidade | H3: Tipo de pagamento | I3: Link Comprovantes
B4: KAMYLLA SUELLY DE ALMEIDA PIRES | C4: 45201 | D4: PZE5G67 | E4: Whatsapp / Sede Petrolina | F4: 300 | G4: 224.91 | H4: PIX | I4: KAMYLLA SUELLY DE ALMEIDA PIRES.jpeg
B5: LAIS SOUZA RIBEIRO ARAUJO | C5: 45203 | D5: PKB4766 | E5: Whatsapp / Sede Itabuna | F5: 100 | G5: 50.9 | H5: PIX | I5: LAIS SOUZA RIBEIRO ARAUJO.pdf
B6: JEFFERSON TEIXEIRA DE JESUS | C6: 45205 | D6: OZJ3D88 | E6: Whatsapp / Sede Juazeiro | F6: 300 | G6: 158.9 | H6: PIX | I6: JEFFERSON TEIXEIRA DE JESUS.jpeg
B7: JOAO VITOR DE OLIVERA BRITO | C7: 45205 | D7: RPY5H97 | E7: Whatsapp / Sede Juazeiro | F7: 180 | G7: 180 | H7: PIX + ESPÉCIE | I7: JOAO VITOR DE OLIVERA BRITO.jpeg
B8: ESTELA CASTRO DA SILVA | C8: 07/10/23 | D8: RCO2D56 | E8: Whatsapp / Online | F8: 120 | G8: 68.9 | H8: PIX | I8: ESTELA CASTRO DA SILVA.jpeg
B9: LUCAS ALISSON DE CRUZ | C9: 07/10/23 | D9: PKG4A34 | E9: Whatsapp / Sede Petrolina | F9: 350 | G9: 239.9 | H9: PIX | I9: LUCAS ALISSON DE CRUZ.jpeg
B10: LUCIANO DE SOUZA ARAUJO | C10: 09/10/23 | D10: ZERO KM | E10: Whatsapp / Sede Petrolina | F10: 200 | G10: 89.9 | H10: DEBITO | I10: LUCIANO DE SOUZA ARAUJO.jpeg
B11: ANCELMO DOS SANTOS LAPSOS | C11: 09/10/23 | D11: PKN9B65 | E11: Whatsapp / Sede Petrolina | F11: 500 | G11: 396.9 | H11: PIX | I11: ANCELMO DOS SANTOS LAPSOS.jpeg
B12: LILIANE FERREIRA PRIMO | C12: 09/10/23 | D12: PGH2326 | E12: Whatsapp / Externa | F12: 100 | G12: 65.46 | H12: ESPÉCIE | I12: LILIANE FERREIRA PRIMO.jpeg
B13: ROGERIO JOSE DE SOUZA | C13: 13/10/23 | D13: SJJ1D54 | E13: Whatsapp / Sede Petrolina | F13: 230 | G13: 88.9 | H13: ESPÉCIE | I13: ROGERIO JOSE DE SOUZA.jpeg
B14: IRAN PEREIRA | C14: 13/10/23 | D14: OYW9J44 | E14: Whatsapp / Online | F14: 105 | G14: 76.9 | H14: PIX | I14: IRAN PEREIRA.pdf
B15: MATEUS LIMA DAMASIO | C15: 13/10/23 | D15: PJS7I69 | E15: Whatsapp / Online | F15: 125 | G15: 78.9 | H15: PIX | I15: MATEUS LIMA DAMASIO.jpeg
B16: RUAN PAULINO NUNES DA SILVA | C16: 17/10/23 | D16: OYQ2H74 | E16: Sede Petrolina | F16: 96 | G16: 68.9 | H16: CREDITO | I16: RUAN PAULINO NUNES DA SILVA.jpeg
B17: RUBENS LOPES DE MIRANDA | C17: 20/10/23 | D17: RNL7C94 | E17: Whatsapp / Online | F17: 300 | G17: 292.9 | H17: CREDITO | I17: RUBENS LOPES DE MIRANDA.jpeg
B18: LAZARO DANTAS RIBEIRO | C18: 24/10/23 | D18: PDW4987 | E18: Whatsapp / Sede Petrolina | F18: 250 | G18: 168.8 | H18: PIX | I18: LAZARO DANTAS RIBEIRO.jpeg
B19: JOSE ADEILSON PEREIRA DOS SANTOS | C19: 24/10/23 | D19: OYL1852 | E19: Whatsapp/ Online | F19: 300 | G19: 134.9 | H19: PIX | I19: JOSE ADEILSON PEREIRA DOS SANTOS.pdf
... B37: ALLYSSON DE JESUS BATISTA | C37: 31/10/23 | D37: QLH4H48 | E37: Whatsapp/ Online | F37: 289.9 | G37: 289.9 | H37: PIX | I37: ALLYSSON DE JESUS BATISTA.pdf
D41: TOTAL ADESÃO | F41: =SUM(F4:F40) -> 7390.41
D42: TOTAL MENSALIDADE | F42: =SUM(G4:G40) -> 4847.71
D43: NUMERO DE PLACAS | F43: =COUNTIF(B4:B1010,"<>") -> 34

Sheet AGOSTO
A1: ADESÃO SETOR COMERCIAL - AGOSTO 2023
A3: Associado | B3: Data de cadastro | C3: Veículo | D3: Origem do Lead | E3: Adesão | F3: Mensalidade | G3: Tipo de pagamento | H3: Atendente | I3: Link Comprovantes
A4: ALCIDES JUNNYOR FERREIRA DE SOUZA | B4: 45139 | C4: XTZ 150 CROSSER Z | D4: Whatsapp / Sede de Petrolina | E4: 150 | F4: 101.9 | G4: Pix | H4: Caroline Beatriz | I4: Erildo Matos Pereira.jpeg
A5: GILSON DA SILVA JUNIOR | B5: 45140 | C5: HILUX CD SRX 4X4 | D5: Whatsapp / Sede de Bonfim | E5: 943.9 | F5: 998.9 | G5: Pix | H5: Caroline Beatriz | I5: GILSON DA SILVA JUNIOR.jpeg
A6: ERILDO MATOS PEREIRA | B6: 45142 | C6: VolksWagen, Saveiro CROSS 1.6 | D6: Whatsapp / Sede Petrolina | E6: 380 | F6: 237.9 | G6: Especie | H6: Caroline Beatriz | I6: ALCIDES JUNNYOR FERREIRA DE SOUZA.jpeg
A7: LOUVERCY RODRIGUES LIMA | B7: 45142 | C7: Chevrolet, TRAILBLAZER LTZ 2.8 | D7: Whatsapp / vistoria a distancia | E7: 535.9 | F7: 535.9 | G7: Pix | H7: Eric Alencar | I7: LOUVERCY RODRIGUES LIMA.jpeg
A8: VALQUIRIA CAMPOS RODRIGUES | B8: 45142 | C8: VolksWagen, JETTA Highline 2.0 | D8: Site / Sede Petrolina | E8: 380 | F8: 307.01 | G8: Cartão | H8: Eric Alencar | I8: VALQUIRIA CAMPOS RODRIGUES.jpeg
A9: GILMAR DE SOUZA LIMA | B9: 45145 | C9: HR-V LX 1.8 2015 | D9: Whatsapp / vistoria a distancia | E9: 277.9 | F9: 277.9 | G9: BOLETO | H9: Caroline Beatriz | I9: GILMAR DE SOUZA LIMA.png
A10: EDIVALDO ALVES DOS SANTOS | B10: 45145 | C10: SIENA FIRE FLEX 2007 | D10: Whatsapp / vistoria a distancia | E10: 65 | F10: 65 | G10: BOLETO | H10: Caroline Beatriz | I10: EDIVALDO ALVES DOS SANTOS.png
A11: JOSE WILSON MACIEL ALVES | B11: 45145 | C11: COROLLA XEI AUT 2015 | D11: Whatsapp / vistoria a distancia | E11: 294.9 | F11: 294.9 | G11: BOLETO | H11: Caroline Beatriz | I11: JOSE WILSON MACIEL ALVES.png
A12: JUSU LOCADORA DE VEICULOS LTDA | B12: 45146 | C12: L200 TRITON GLS 2.4 CD DIESEL | D12: Sede Petrolina | E12: 504.45 | F12: 504.45 | G12: BOLETO | H12: Eric Alencar | I12: JUSU LOCADORA DE VEICULOS LTDA.png
A13: LARYSSA EMANUELLA SOUZA DIAS DE MORAES | B13: 45146 | C13: SHINERAY, 50-Q RAY Zero KM | D13: Site / Sede Petrolina | E13: 150 | F13: 65.9 | G13: Cartão | H13: Eric Alencar | I13: Laryssa Emanuela Souza dias de Moraes.jpeg
A14: MARIA ROSICLEIDE NUNES DE CARVALHO | B14: 45148 | C14: Fiat, MOBI LIKE 1.0 2022 | D14: Sede Petrolina | E14: 180 | F14: 180 | G14: BOLETO | H14: Caroline Beatriz
A15: RUAN PAULINO NUNES DA SILVA | B15: 45149 | C15: XTZ 150 CROSSER Z | D15: Sede Petrolina | E15: 100 | F15: 77.31 | G15: Cartão | H15: Caroline Beatriz | I15: RUAN PAULINO NUNES DA SILVA.pdf
A16: FRANCISCO MAYCON BORGES DE OLIVEIRA | B16: 45154 | C16: HONDA, NXR 160 BROS | D16: Whatsapp / vistoria a distancia | E16: 150 | F16: 79.71 | G16: Cartão | H16: Caroline Beatriz | I16: FRANCISCO MAYCON BORGES DE OLIVEIRA.jpeg
A17: JOABE GONCALVES FERREIRA SANTOS | B17: 45155 | C17: Hilux SW4 SRV D4-D 4x4 2012 | D17: Whatsapp / vistoria a distancia | E17: 585 | F17: 530.91 | G17: Pix | H17: Caroline Beatriz | I17: JOABE GONCALVES FERREIRA SANTOS.jpeg
A18: JOSE NEI ALMEIDA SANTOS | B18: 45156 | C18: Fiat, ARGO DRIVE 1.0 2020 | D18: Whatsapp / vistoria a distancia | E18: 300 | F18: 272.9 | G18: Pix | H18: Caroline Beatriz | I18: JOSE NEI ALMEIDA SANTOS.jpeg
A19: Cesar Brito Gonzaga | B19: 45159 | C19: HONDA, CG 160 START Zero KM | D19: Whatsapp / vistoria a distancia | E19: 150 | F19: 59.9 | G19: Pix | H19: Eric Alencar | I19: Cesar Brito Gonzaga.jpeg
A20: Willames Mateus De Andrade Costa | B20: 45159 | C20: VolksWagen, Gol (Novo) 1.0 Mi | D20: Whatsapp / Sede Petrolina | E20: 154.9 | F20: 154.9 | G20: Pix | H20: Caroline Beatriz | I20: Willames Mateus De Andrade Costa.pdf
A21: JOÃO VITOR FERREIRA DOS SANTOS | B21: 45159 | C21: YAMAHA, FZ15 150 ZERO KM | D21: Whatsapp / vistoria a distancia | E21: 200 | F21: 90.9 | G21: Pix | H21: Eric Alencar | I21: JOAO VITOR FERREIRA DOS SANTOS.jpeg
A22: HORACIO HUDSON GOMES DA SILVA | B22: 45161 | C22: Fiat Palio 1.0 ECONOMY 2012 | D22: DIRETORIA - POLLIANA | E22: 0 | F22: 115 | H22: Eric Alencar
A23: EULINA GRASIELLE DA SILVA CÉZAR | B23: 45162 | C23: HONDA NXR 160 BROS ZERO | D23: Whatsapp / vistoria em Juazeiro | E23: 200 | F23: 98.9 | G23: Pix | H23: Eric Alencar | I23: EULINA GRASIELLE DA SILVA CÉZAR.jpeg
A24: ADEVALDO PAIXAO DA SILVA | B24: 45163 | C24: HONDA CG 160 TITAN | D24: Whatsapp / Sede Petrolina | E24: 59.9 | F24: 59.9 | G24: Debito | H24: Caroline Beatriz | I24: ADEVALDO PAIXAO DA SILVA.jpeg
A25: Paulo Luciano Pimentel Nunes | B25: 45164 | C25: Honda CITY Sedan EX 2011 | D25: Whatsapp / vistoria a distancia | E25: 280 | F25: 246.9 | G25: Pix | H25: Eric Alencar | I25: Paulo Luciano Pimentel Nunes.jpeg
A26: HELENO GOMES DE LIRA | B26: 45168 | C26: HONDA NXR 150 BROS | D26: Whatsapp / vistoria a distancia | E26: 75.9 | F26: 75.9 | G26: BOLETO | H26: Eric Alencar
A27: RUAN PAULINO NUNES DA SILVA | B27: 45168 | C27: HONDA CG 150 START | D27: Sede Petrolina | E27: 71.9 | F27: 71.9 | G27: Cartão | H27: Caroline Beatriz | I27: RUAN PAULINO NUNES DA SILVA.jpeg
A28: CICERO ANDERSON BARROS DA SILVA | B28: 45168 | C28: HONDA CG 160 FAN 2023 | D28: Whatsapp / vistoria a distancia | E28: 59.9 | F28: 59.9 | G28: Pix | H28: Eric Alencar | I28: CICERO ANDERSON BARROS DA SILVA.jpeg
A29: HERNANY GOMES COSTA | B29: 45169 | C29: Ford Ka 1.0 SEL 2019 | D29: Whatsapp | E29: 200 | F29: 171.9 | G29: Pix | H29: Eric Alencar | I29: HERNANY GOMES COSTA.pdf
A30: MARIVANE REIS BRITTO | B30: 45169 | C30: Chevrolet S10 Pick-Up 2004 | D30: Whatsapp / Vistoria externa | E30: 300 | F30: 188.9 | G30: Pix | H30: Eric Alencar | I30: MARIVANE REIS BRITTO.jpeg
A31: NOABE NOGUEIRA DOS SANTOS | B31: 45169 | C31: Chevrolet SPIN LTZ 2019 | D31: Whatsapp / Vistoria externa | E31: 350 | F31: 265.41 | G31: Pix | H31: Eric Alencar | I31: NOABE NOGUEIRA DOS SANTOS.pdf
C33: TOTAL ADESÃO | D33: =SUM(E4:E32) -> 7099.55
C34: TOTAL MENSALIDADE | D34: =SUM(F3:F26) -> 5432.89
C35: NUMERO DE PLACAS | D35: =COUNTIF(A4:A1002,"<>") -> 28

Sheet JULHO
A1: ADESÃO SETOR COMERCIAL - JULHO 2023
A3: Associado | B3: Data de cadastro | C3: Veículo | D3: Origem do Lead | E3: Adesão | F3: Mensalidade | G3: Tipo de pagamento | H3: Atendente
A4: Neirivaldo Lacio da Silva Souza | B4: 45110 | C4: Ybr 125 Factor | D4: Sede de Petrolina | E4: 0 | F4: 53.9 | G4: Insentado | H4: Caroline Beatriz
A5: Osvaldo Rodrigues | B5: 45110 | C5: Cg 150 Fan | D5: Sede de Petrolina | E5: 120 | F5: 54.9 | G5: Pix | H5: Caroline Beatriz
A6: Franciele Lima da Silva | B6: 45110 | C6: NXR BROS 160 | D6: WhatsApp / Vistoria Sede de juazeiro | E6: 150 | F6: 98.9 | G6: Dinheiro/ Sede de juazeiro | H6: Eric Alencar
A7: JUSU LOCADORA DE VEICULOS LTDA | B7: 45110 | C7: DUSTER Zen 1.6 2021 | D7: Sede de Petrolina | E7: 0 | F7: 335.9 | G7: Insentado | H7: Eric Alencar
A8: JUSU LOCADORA DE VEICULOS LTDA | B8: 45110 | C8: Frontier ATTAC.CD 2021 | D8: Sede de Petrolina | E8: 0 | F8: 748.9 | G8: Insentado | H8: Eric Alencar
A9: Ronildo França da Silva | B9: 45113 | C9: CG 150 FAN | D9: WhatsApp / Vistoria a distancia | E9: 120 | F9: 54.9 | G9: Pix | H9: Caroline Beatriz
A10: Joao Marcos Gomes de Lima | B10: 45113 | C10: HONDA 160 CG | D10: Sede de Petrolina | E10: 73.9 | F10: 73.9 | G10: Débito | H10: Caroline Beatriz
A11: LAELIA OLIVEIRA MOURA | B11: 45113 | C11: Fox Comfortline 1.6 | D11: Whatsapp / Vistoria a distancia | E11: 184.41 | F11: 184.41 | G11: Débito | H11: Eric Alencar
A12: OTAVIO BRENO ESCOBAR DOS SANTOS | B12: 45114 | C12: Cg 160 Fintan | D12: Sede de Petrolina | E12: 75.9 | F12: 88.9 | G12: Pix | H12: Caroline Beatriz
A13: FLAVIA EDUARDA DA SILVA BARROS | B13: 45117 | C13: MERCEDES-BENZ, Axor 2536 S/LS 6x2 | D13: Whatsapp / Vistoria externa | E13: 1850 | F13: 849.9 | G13: Pix | H13: Eric Alencar
A14: JOAO CARLOS DA CONCEICAO SILVA | B14: 45117 | C14: Toyota, Corolla XEi 2.0 | D14: Whatsapp / Vistoria a distancia | E14: 400 | F14: 390.9 | G14: Pix | H14: Eric Alencar
A15: HENRIQUE CAVALCANTE DE AMORIM | B15: 45118 | C15: Fiat, Doblo Cargo 1.8 2009 | D15: Whatsapp/ Vistoria a distancia | E15: 200 | F15: 127.91 | G15: Pix | H15: Caroline Beatriz
... A37: GEIDSON MAICLEI RIBEIRO LOPES | B37: 45138 | C37: Onix HATCH LT 1.0 | D37: Whatsapp/ Vistoria a distancia | E37: 171.9 | F37: 171.9 | G37: Pix | H37: Caroline Beatriz
C39: TOTAL ADESÃO | D39: =SUM(E4:E38) -> 7422.61
C40: TOTAL MENSALIDADE | D40: =SUM(F4:F38) -> 6736.56
C41: NUMERO DE PLACAS | D41: 34
